Workbook

Sheet Dashboard
A1: JOB SEARCH COMMAND CENTER
A3: David St. Julus — Accountant · Bookkeeping · Financial Analysis | New Hampshire & Massachusetts | P3: CHART DATA — live formulas, auto-calculate (no pivot refresh needed)
A4: ="Updated: "&TEXT(TODAY(),"dddd, mmm d, yyyy")&" (times in Eastern)" -> Updated: Friday, Oct 23, 2026 (times in Eastern)
P5: Pipeline Stage | Q5: Count | U5: Week Of | V5: Applications
A6: =COUNTA(Jobs!$A$2:$A$1000) -> 50 | C6: =COUNT(Jobs!$T$2:$T$1000) -> 0 | E6: =COUNT(Jobs!$U$2:$U$1000) -> 0 | G6: =COUNT(Jobs!$V$2:$V$1000) -> 0 | I6: =COUNT(Jobs!$X$2:$X$1000) -> 0 | K6: =COUNT(Jobs!$Y$2:$Y$1000) -> 0 | M6: =COUNT(Jobs!$Z$2:$Z$1000) -> 0 | P6: Total Fits | Q6: =$A$6 -> 50 | U6: 46300 | V6: =COUNTIFS(Jobs!$T$2:$T$1000,">="&U6,Jobs!$T$2:$T$1000,"<"&U6+7) -> 0
P7: Applied | Q7: =$C$6 -> 0 | U7: 46307 | V7: =COUNTIFS(Jobs!$T$2:$T$1000,">="&U7,Jobs!$T$2:$T$1000,"<"&U7+7) -> 0
A8: TOTAL FITS | C8: APPLIED | E8: CONTACTED | G8: RESPONSES | I8: INTERVIEWS | K8: OFFERS | M8: REJECTIONS | P8: Contacted | Q8: =$E$6 -> 0 | U8: 46314 | V8: =COUNTIFS(Jobs!$T$2:$T$1000,">="&U8,Jobs!$T$2:$T$1000,"<"&U8+7) -> 0
P9: Responded | Q9: =$G$6 -> 0 | U9: 46321 | V9: =COUNTIFS(Jobs!$T$2:$T$1000,">="&U9,Jobs!$T$2:$T$1000,"<"&U9+7) -> 0
P10: Interview | Q10: =$I$6 -> 0 | U10: 46328 | V10: =COUNTIFS(Jobs!$T$2:$T$1000,">="&U10,Jobs!$T$2:$T$1000,"<"&U10+7) -> 0
A11: =IF($C$6=0,0,$G$6/$C$6) -> 0 | C11: =IF($C$6=0,0,$I$6/$C$6) -> 0 | E11: =IF($C$6=0,0,$K$6/$C$6) -> 0 | G11: =IF(SUMPRODUCT((Jobs!$V$2:$V$1000<>"")*(Jobs!$T$2:$T$1000<>""))=0,"—",SUMPRODUCT((Jobs!$V$2:$V$1000<>"")*(Jobs!$T$2:$T$1000<>"")*(Jobs!$V$2:$V$1000-Jobs!$T$2:$T$1000))/SUMPRODUCT((Jobs!$V$2:$V$1000<>"")*(Jobs!$T$2:$T$1000<>""))) -> — | I11: =COUNTIF(Jobs!$AC$2:$AC$1000,"DUE") -> 0 | K11: =COUNTIF(Jobs!$AD$2:$AD$1000,"GHOSTED") -> 0 | M11: =$A$6-$M$6-COUNTIF(Jobs!$AD$2:$AD$1000,"GHOSTED") -> 50 | P11: Offer | Q11: =$K$6 -> 0 | U11: 46335 | V11: =COUNTIFS(Jobs!$T$2:$T$1000,">="&U11,Jobs!$T$2:$T$1000,"<"&U11+7) -> 0
U12: 46342 | V12: =COUNTIFS(Jobs!$T$2:$T$1000,">="&U12,Jobs!$T$2:$T$1000,"<"&U12+7) -> 0
A13: RESPONSE RATE | C13: INTERVIEW RATE | E13: OFFER RATE | G13: AVG DAYS → RESPONSE | I13: FOLLOW-UPS DUE | K13: GHOSTED (30d+) | M13: ACTIVE PIPELINE | P13: Industry | Q13: Identified | R13: Applied | U13: 46349 | V13: =COUNTIFS(Jobs!$T$2:$T$1000,">="&U13,Jobs!$T$2:$T$1000,"<"&U13+7) -> 0
P14: Accounting (CPA firms) | Q14: =COUNTIF(Jobs!$D$2:$D$1000,P14) -> 10 | R14: =COUNTIFS(Jobs!$D$2:$D$1000,P14,Jobs!$T$2:$T$1000,"<>") -> 0 | U14: 46356 | V14: =COUNTIFS(Jobs!$T$2:$T$1000,">="&U14,Jobs!$T$2:$T$1000,"<"&U14+7) -> 0
A15: PIPELINE · INDUSTRY · PACE · SOURCE | P15: Accounting (corporate / industry) | Q15: =COUNTIF(Jobs!$D$2:$D$1000,P15) -> 23 | R15: =COUNTIFS(Jobs!$D$2:$D$1000,P15,Jobs!$T$2:$T$1000,"<>") -> 0 | U15: 46363 | V15: =COUNTIFS(Jobs!$T$2:$T$1000,">="&U15,Jobs!$T$2:$T$1000,"<"&U15+7) -> 0
P16: Government | Q16: =COUNTIF(Jobs!$D$2:$D$1000,P16) -> 2 | R16: =COUNTIFS(Jobs!$D$2:$D$1000,P16,Jobs!$T$2:$T$1000,"<>") -> 0 | U16: 46370 | V16: =COUNTIFS(Jobs!$T$2:$T$1000,">="&U16,Jobs!$T$2:$T$1000,"<"&U16+7) -> 0
P17: Nonprofit | Q17: =COUNTIF(Jobs!$D$2:$D$1000,P17) -> 4 | R17: =COUNTIFS(Jobs!$D$2:$D$1000,P17,Jobs!$T$2:$T$1000,"<>") -> 0 | U17: 46377 | V17: =COUNTIFS(Jobs!$T$2:$T$1000,">="&U17,Jobs!$T$2:$T$1000,"<"&U17+7) -> 0
P18: Finance | Q18: =COUNTIF(Jobs!$D$2:$D$1000,P18) -> 8 | R18: =COUNTIFS(Jobs!$D$2:$D$1000,P18,Jobs!$T$2:$T$1000,"<>") -> 0 | U18: 46384 | V18: =COUNTIFS(Jobs!$T$2:$T$1000,">="&U18,Jobs!$T$2:$T$1000,"<"&U18+7) -> 0
P19: Business operations | Q19: =COUNTIF(Jobs!$D$2:$D$1000,P19) -> 2 | R19: =COUNTIFS(Jobs!$D$2:$D$1000,P19,Jobs!$T$2:$T$1000,"<>") -> 0 | U19: 46391 | V19: =COUNTIFS(Jobs!$T$2:$T$1000,">="&U19,Jobs!$T$2:$T$1000,"<"&U19+7) -> 0
P20: Tech / AI | Q20: =COUNTIF(Jobs!$D$2:$D$1000,P20) -> 1 | R20: =COUNTIFS(Jobs!$D$2:$D$1000,P20,Jobs!$T$2:$T$1000,"<>") -> 0 | U20: 46398 | V20: =COUNTIFS(Jobs!$T$2:$T$1000,">="&U20,Jobs!$T$2:$T$1000,"<"&U20+7) -> 0
P21: Sales | Q21: =COUNTIF(Jobs!$D$2:$D$1000,P21) -> 0 | R21: =COUNTIFS(Jobs!$D$2:$D$1000,P21,Jobs!$T$2:$T$1000,"<>") -> 0 | U21: 46405 | V21: =COUNTIFS(Jobs!$T$2:$T$1000,">="&U21,Jobs!$T$2:$T$1000,"<"&U21+7) -> 0
P22: Sports business | Q22: =COUNTIF(Jobs!$D$2:$D$1000,P22) -> 0 | R22: =COUNTIFS(Jobs!$D$2:$D$1000,P22,Jobs!$T$2:$T$1000,"<>") -> 0
P23: Other | Q23: =COUNTIF(Jobs!$D$2:$D$1000,P23) -> 0 | R23: =COUNTIFS(Jobs!$D$2:$D$1000,P23,Jobs!$T$2:$T$1000,"<>") -> 0
P25: Source | Q25: Applied | R25: Responses | S25: Resp. Rate
P26: Indeed | Q26: =COUNTIFS(Jobs!$N$2:$N$1000,P26,Jobs!$T$2:$T$1000,"<>") -> 0 | R26: =COUNTIFS(Jobs!$N$2:$N$1000,P26,Jobs!$V$2:$V$1000,"<>") -> 0 | S26: =IF(Q26=0,0,R26/Q26) -> 0
P27: ZipRecruiter | Q27: =COUNTIFS(Jobs!$N$2:$N$1000,P27,Jobs!$T$2:$T$1000,"<>") -> 0 | R27: =COUNTIFS(Jobs!$N$2:$N$1000,P27,Jobs!$V$2:$V$1000,"<>") -> 0 | S27: =IF(Q27=0,0,R27/Q27) -> 0
P28: LinkedIn | Q28: =COUNTIFS(Jobs!$N$2:$N$1000,P28,Jobs!$T$2:$T$1000,"<>") -> 0 | R28: =COUNTIFS(Jobs!$N$2:$N$1000,P28,Jobs!$V$2:$V$1000,"<>") -> 0 | S28: =IF(Q28=0,0,R28/Q28) -> 0
P29: Company site | Q29: =COUNTIFS(Jobs!$N$2:$N$1000,P29,Jobs!$T$2:$T$1000,"<>") -> 0 | R29: =COUNTIFS(Jobs!$N$2:$N$1000,P29,Jobs!$V$2:$V$1000,"<>") -> 0 | S29: =IF(Q29=0,0,R29/Q29) -> 0
P30: Referral | Q30: =COUNTIFS(Jobs!$N$2:$N$1000,P30,Jobs!$T$2:$T$1000,"<>") -> 0 | R30: =COUNTIFS(Jobs!$N$2:$N$1000,P30,Jobs!$V$2:$V$1000,"<>") -> 0 | S30: =IF(Q30=0,0,R30/Q30) -> 0
P31: Manual | Q31: =COUNTIFS(Jobs!$N$2:$N$1000,P31,Jobs!$T$2:$T$1000,"<>") -> 0 | R31: =COUNTIFS(Jobs!$N$2:$N$1000,P31,Jobs!$V$2:$V$1000,"<>") -> 0 | S31: =IF(Q31=0,0,R31/Q31) -> 0

Sheet Jobs
A1: Job ID | B1: Date Found | C1: Date Posted | D1: Industry | E1: Company | F1: Title | G1: Location | H1: Work Mode | I1: Job Type | J1: Pay Range (raw) | K1: Annual Low $ | L1: Annual High $ | M1: Annual Mid $ | N1: Source | O1: Apply Link | P1: Fit (1-5) | Q1: Why It Fits You | R1: Resume Version | S1: Stage | T1: Applied | U1: Contacted | V1: Response | W1: Follow-up Sent | X1: Interview | Y1: Offer | Z1: Rejected | AA1: Next Action Date | AB1: Days Since Applied | AC1: Follow-up Due? | AD1: Ghosted? | AE1: Rejection Reason | AF1: Dup Key | AG1: Dup?
A2: 2026-10-001 | B2: 46318 | C2: 46297 | D2: Accounting (CPA firms) | E2: Feature Solutions | F2: Bookkeeper – Part-Time (QuickBooks Online) | G2: Manchester, NH | H2: On-site | I2: Part-time | J2: $18–$23/hr | K2: 37440 | L2: 47840 | M2: =IF(AND(K2="",L2=""),"",IF(L2="",K2,IF(K2="",L2,ROUND(AVERAGE(K2:L2),0)))) -> 42640 | N2: Indeed | O2: Apply ↗ | P2: 5 | Q2: Direct QBO bookkeeping match — your core daily tool | R2: Master | S2: Identified | AB2: =IF(T2="","",TODAY()-T2) | AC2: =IF(T2="","",IF(V2<>"","",IF(TODAY()-T2>=7,"DUE",""))) | AD2: =IF(T2="","",IF(AND(V2="",TODAY()-T2>=30),"GHOSTED","")) | AF2: =IF(E2="","",LOWER(E2&" | "&F2&" | "&G2)) -> feature solutions | bookkeeper – part-time (quickbooks online) | manchester, nh | AG2: =IF(AF2="","",IF(COUNTIF($AF$2:$AF$1000,AF2)>1,"DUP",""))
A3: 2026-10-002 | B3: 46318 | C3: 46301 | D3: Accounting (CPA firms) | E3: Business Cents | F3: Senior Bookkeeper | G3: Manchester, NH | H3: On-site | I3: Full-time | J3: $25–$30/hr | K3: 52000 | L3: 62400 | M3: =IF(AND(K3="",L3=""),"",IF(L3="",K3,IF(K3="",L3,ROUND(AVERAGE(K3:L3),0)))) -> 57200 | N3: Indeed | O3: Apply ↗ | P3: 5 | Q3: Full-charge bookkeeping for a local firm; multi-client like your current work | R3: Master | S3: Identified | AB3: =IF(T3="","",TODAY()-T3) | AC3: =IF(T3="","",IF(V3<>"","",IF(TODAY()-T3>=7,"DUE",""))) | AD3: =IF(T3="","",IF(AND(V3="",TODAY()-T3>=30),"GHOSTED","")) | AF3: =IF(E3="","",LOWER(E3&" | "&F3&" | "&G3)) -> business cents | senior bookkeeper | manchester, nh | AG3: =IF(AF3="","",IF(COUNTIF($AF$2:$AF$1000,AF3)>1,"DUP",""))
A4: 2026-10-003 | B4: 46318 | C4: 46299 | D4: Business operations | E4: 3 Lions Logistics | F4: Bookkeeper/ Staff Accountant | G4: Salem, NH | H4: On-site | I4: Full-time | J4: $65,000–$70,000 | K4: 65000 | L4: 70000 | M4: =IF(AND(K4="",L4=""),"",IF(L4="",K4,IF(K4="",L4,ROUND(AVERAGE(K4:L4),0)))) -> 67500 | N4: Indeed | O4: Apply ↗ | P4: 5 | Q4: Combined bookkeeping + staff accounting — fits your hybrid skill set | R4: Master | S4: Identified | AB4: =IF(T4="","",TODAY()-T4) | AC4: =IF(T4="","",IF(V4<>"","",IF(TODAY()-T4>=7,"DUE",""))) | AD4: =IF(T4="","",IF(AND(V4="",TODAY()-T4>=30),"GHOSTED","")) | AF4: =IF(E4="","",LOWER(E4&" | "&F4&" | "&G4)) -> 3 lions logistics | bookkeeper/ staff accountant | salem, nh | AG4: =IF(AF4="","",IF(COUNTIF($AF$2:$AF$1000,AF4)>1,"DUP",""))
A5: 2026-10-004 | B5: 46318 | C5: 46293 | D5: Business operations | E5: 3 Lions Logistics | F5: Junior Accountant | G5: Salem, NH | H5: On-site | I5: Full-time | J5: $58,380–$70,307 | K5: 58380 | L5: 70307 | M5: =IF(AND(K5="",L5=""),"",IF(L5="",K5,IF(K5="",L5,ROUND(AVERAGE(K5:L5),0)))) -> 64344 | N5: Indeed | O5: Apply ↗ | P5: 5 | Q5: Entry/junior accountant role — reconciliations and journal entries | R5: Master | S5: Identified | AB5: =IF(T5="","",TODAY()-T5) | AC5: =IF(T5="","",IF(V5<>"","",IF(TODAY()-T5>=7,"DUE",""))) | AD5: =IF(T5="","",IF(AND(V5="",TODAY()-T5>=30),"GHOSTED","")) | AF5: =IF(E5="","",LOWER(E5&" | "&F5&" | "&G5)) -> 3 lions logistics | junior accountant | salem, nh | AG5: =IF(AF5="","",IF(COUNTIF($AF$2:$AF$1000,AF5)>1,"DUP",""))
A6: 2026-10-005 | B6: 46318 | C6: 46273 | D6: Accounting (corporate / industry) | E6: Scott Electronics, Inc. | F6: Staff Accountant | G6: Salem, NH | H6: On-site | I6: Full-time | J6: $30–$35/hr | K6: 62400 | L6: 72800 | M6: =IF(AND(K6="",L6=""),"",IF(L6="",K6,IF(K6="",L6,ROUND(AVERAGE(K6:L6),0)))) -> 67600 | N6: Indeed | O6: Apply ↗ | P6: 5 | Q6: Classic staff accountant duties matching your full-cycle experience | R6: Master | S6: Identified | AB6: =IF(T6="","",TODAY()-T6) | AC6: =IF(T6="","",IF(V6<>"","",IF(TODAY()-T6>=7,"DUE",""))) | AD6: =IF(T6="","",IF(AND(V6="",TODAY()-T6>=30),"GHOSTED","")) | AF6: =IF(E6="","",LOWER(E6&" | "&F6&" | "&G6)) -> scott electronics, inc. | staff accountant | salem, nh | AG6: =IF(AF6="","",IF(COUNTIF($AF$2:$AF$1000,AF6)>1,"DUP",""))
A7: 2026-10-006 | B7: 46318 | C7: 46203 | D7: Accounting (corporate / industry) | E7: Paul Davis Restoration | F7: Reconstruction Job Cost Accountant | G7: Salem, NH | H7: On-site | I7: Full-time | J7: $50,000–$60,000 | K7: 50000 | L7: 60000 | M7: =IF(AND(K7="",L7=""),"",IF(L7="",K7,IF(K7="",L7,ROUND(AVERAGE(K7:L7),0)))) -> 55000 | N7: Indeed | O7: Apply ↗ | P7: 3 | Q7: Job-cost accounting; builds on your profitability/unit-economics work | R7: Master | S7: Identified | AB7: =IF(T7="","",TODAY()-T7) | AC7: =IF(T7="","",IF(V7<>"","",IF(TODAY()-T7>=7,"DUE",""))) | AD7: =IF(T7="","",IF(AND(V7="",TODAY()-T7>=30),"GHOSTED","")) | AF7: =IF(E7="","",LOWER(E7&" | "&F7&" | "&G7)) -> paul davis restoration | reconstruction job cost accountant | salem, nh | AG7: =IF(AF7="","",IF(COUNTIF($AF$2:$AF$1000,AF7)>1,"DUP",""))
A8: 2026-10-007 | B8: 46318 | C8: 46311 | D8: Accounting (corporate / industry) | E8: Goedecke Flooring & Design | F8: Bookkeeper & HR Administrator | G8: Bedford, NH | H8: On-site | I8: Full-time | J8: $62,000–$75,000 | K8: 62000 | L8: 75000 | M8: =IF(AND(K8="",L8=""),"",IF(L8="",K8,IF(K8="",L8,ROUND(AVERAGE(K8:L8),0)))) -> 68500 | N8: Indeed | O8: Apply ↗ | P8: 5 | Q8: Full-charge bookkeeping for a small business — your sweet spot | R8: Master | S8: Identified | AB8: =IF(T8="","",TODAY()-T8) | AC8: =IF(T8="","",IF(V8<>"","",IF(TODAY()-T8>=7,"DUE",""))) | AD8: =IF(T8="","",IF(AND(V8="",TODAY()-T8>=30),"GHOSTED","")) | AF8: =IF(E8="","",LOWER(E8&" | "&F8&" | "&G8)) -> goedecke flooring & design | bookkeeper & hr administrator | bedford, nh | AG8: =IF(AF8="","",IF(COUNTIF($AF$2:$AF$1000,AF8)>1,"DUP",""))
A9: 2026-10-008 | B9: 46318 | C9: 46295 | D9: Accounting (corporate / industry) | E9: Generator Pro / Spa Guy | F9: Assistant Bookkeeper / Office Assistant | G9: Nashua, NH | H9: On-site | I9: Full-time | J9: $20–$29/hr | K9: 41600 | L9: 60320 | M9: =IF(AND(K9="",L9=""),"",IF(L9="",K9,IF(K9="",L9,ROUND(AVERAGE(K9:L9),0)))) -> 50960 | N9: Indeed | O9: Apply ↗ | P9: 3 | Q9: Bookkeeping support role, easy entry near Manchester | R9: Master | S9: Identified | AB9: =IF(T9="","",TODAY()-T9) | AC9: =IF(T9="","",IF(V9<>"","",IF(TODAY()-T9>=7,"DUE",""))) | AD9: =IF(T9="","",IF(AND(V9="",TODAY()-T9>=30),"GHOSTED","")) | AF9: =IF(E9="","",LOWER(E9&" | "&F9&" | "&G9)) -> generator pro / spa guy | assistant bookkeeper / office assistant | nashua, nh | AG9: =IF(AF9="","",IF(COUNTIF($AF$2:$AF$1000,AF9)>1,"DUP",""))
A10: 2026-10-009 | B10: 46318 | C10: 46310 | D10: Accounting (CPA firms) | E10: Stephens-Marquis Associates | F10: Accounting Administrator | G10: Merrimack, NH | H10: On-site | I10: Full-time | J10: $58,000–$66,000 | K10: 58000 | L10: 66000 | M10: =IF(AND(K10="",L10=""),"",IF(L10="",K10,IF(K10="",L10,ROUND(AVERAGE(K10:L10),0)))) -> 62000 | N10: Indeed | O10: Apply ↗ | P10: 5 | Q10: Full accounting admin for a small firm; QBO/Excel focused | R10: Master | S10: Identified | AB10: =IF(T10="","",TODAY()-T10) | AC10: =IF(T10="","",IF(V10<>"","",IF(TODAY()-T10>=7,"DUE",""))) | AD10: =IF(T10="","",IF(AND(V10="",TODAY()-T10>=30),"GHOSTED","")) | AF10: =IF(E10="","",LOWER(E10&" | "&F10&" | "&G10)) -> stephens-marquis associates | accounting administrator | merrimack, nh | AG10: =IF(AF10="","",IF(COUNTIF($AF$2:$AF$1000,AF10)>1,"DUP",""))
A11: 2026-10-010 | B11: 46318 | C11: 46080 | D11: Accounting (corporate / industry) | E11: JLS Mailing Services | F11: Bookkeeper/Accounts Administrator | G11: Concord, NH | H11: On-site | I11: Full-time | J11: $54,930–$87,662 | K11: 54930 | L11: 87662 | M11: =IF(AND(K11="",L11=""),"",IF(L11="",K11,IF(K11="",L11,ROUND(AVERAGE(K11:L11),0)))) -> 71296 | N11: Indeed | O11: Apply ↗ | P11: 5 | Q11: Full-charge bookkeeping with strong pay range | R11: Master | S11: Identified | AB11: =IF(T11="","",TODAY()-T11) | AC11: =IF(T11="","",IF(V11<>"","",IF(TODAY()-T11>=7,"DUE",""))) | AD11: =IF(T11="","",IF(AND(V11="",TODAY()-T11>=30),"GHOSTED","")) | AF11: =IF(E11="","",LOWER(E11&" | "&F11&" | "&G11)) -> jls mailing services | bookkeeper/accounts administrator | concord, nh | AG11: =IF(AF11="","",IF(COUNTIF($AF$2:$AF$1000,AF11)>1,"DUP",""))
A12: 2026-10-011 | B12: 46318 | C12: 46237 | D12: Accounting (corporate / industry) | E12: Ford of Londonderry | F12: Accounting/Administration | G12: Londonderry, NH | H12: On-site | I12: Full-time | J12: N/A | M12: =IF(AND(K12="",L12=""),"",IF(L12="",K12,IF(K12="",L12,ROUND(AVERAGE(K12:L12),0)))) | N12: Indeed | O12: Apply ↗ | P12: 3 | Q12: Dealership accounting office — transaction-heavy reconciliation work | R12: Master | S12: Identified | AB12: =IF(T12="","",TODAY()-T12) | AC12: =IF(T12="","",IF(V12<>"","",IF(TODAY()-T12>=7,"DUE",""))) | AD12: =IF(T12="","",IF(AND(V12="",TODAY()-T12>=30),"GHOSTED","")) | AF12: =IF(E12="","",LOWER(E12&" | "&F12&" | "&G12)) -> ford of londonderry | accounting/administration | londonderry, nh | AG12: =IF(AF12="","",IF(COUNTIF($AF$2:$AF$1000,AF12)>1,"DUP",""))
A13: 2026-10-012 | B13: 46318 | C13: 46227 | D13: Nonprofit | E13: Pine Haven Boys Center | F13: Financial Operations Specialist | G13: Suncook, NH | H13: On-site | I13: Full-time | J13: $60,000–$70,000 | K13: 60000 | L13: 70000 | M13: =IF(AND(K13="",L13=""),"",IF(L13="",K13,IF(K13="",L13,ROUND(AVERAGE(K13:L13),0)))) -> 65000 | N13: Indeed | O13: Apply ↗ | P13: 5 | Q13: Finance operations + reporting; mirrors your fractional-CFO duties | R13: Master | S13: Identified | AB13: =IF(T13="","",TODAY()-T13) | AC13: =IF(T13="","",IF(V13<>"","",IF(TODAY()-T13>=7,"DUE",""))) | AD13: =IF(T13="","",IF(AND(V13="",TODAY()-T13>=30),"GHOSTED","")) | AF13: =IF(E13="","",LOWER(E13&" | "&F13&" | "&G13)) -> pine haven boys center | financial operations specialist | suncook, nh | AG13: =IF(AF13="","",IF(COUNTIF($AF$2:$AF$1000,AF13)>1,"DUP",""))
A14: 2026-10-013 | B14: 46318 | C14: 46302 | D14: Accounting (corporate / industry) | E14: Spectrum Marketing Companies | F14: Accounting Associate | G14: Manchester, NH | H14: On-site | I14: Full-time | J14: $22–$25/hr | K14: 45760 | L14: 52000 | M14: =IF(AND(K14="",L14=""),"",IF(L14="",K14,IF(K14="",L14,ROUND(AVERAGE(K14:L14),0)))) -> 48880 | N14: Indeed | O14: Apply ↗ | P14: 5 | Q14: Local Manchester accounting support role — short commute | R14: Master | S14: Identified | AB14: =IF(T14="","",TODAY()-T14) | AC14: =IF(T14="","",IF(V14<>"","",IF(TODAY()-T14>=7,"DUE",""))) | AD14: =IF(T14="","",IF(AND(V14="",TODAY()-T14>=30),"GHOSTED","")) | AF14: =IF(E14="","",LOWER(E14&" | "&F14&" | "&G14)) -> spectrum marketing companies | accounting associate | manchester, nh | AG14: =IF(AF14="","",IF(COUNTIF($AF$2:$AF$1000,AF14)>1,"DUP",""))
A15: 2026-10-014 | B15: 46318 | C15: 46300 | D15: Finance | E15: Buchanan Technologies | F15: Sr. Financial Planning & Analysis Analyst | G15: Manchester, NH | H15: On-site | I15: Full-time | J15: $75,000–$90,000 | K15: 75000 | L15: 90000 | M15: =IF(AND(K15="",L15=""),"",IF(L15="",K15,IF(K15="",L15,ROUND(AVERAGE(K15:L15),0)))) -> 82500 | N15: Indeed | O15: Apply ↗ | P15: 5 | Q15: FP&A role matching your KPI dashboards, budgeting & forecasting | R15: Master | S15: Identified | AB15: =IF(T15="","",TODAY()-T15) | AC15: =IF(T15="","",IF(V15<>"","",IF(TODAY()-T15>=7,"DUE",""))) | AD15: =IF(T15="","",IF(AND(V15="",TODAY()-T15>=30),"GHOSTED","")) | AF15: =IF(E15="","",LOWER(E15&" | "&F15&" | "&G15)) -> buchanan technologies | sr. financial planning & analysis analyst | manchester, nh | AG15: =IF(AF15="","",IF(COUNTIF($AF$2:$AF$1000,AF15)>1,"DUP",""))
A16: 2026-10-015 | B16: 46318 | C16: 46317 | D16: Nonprofit | E16: Breathe New Hampshire | F16: Accounting Manager | G16: Manchester, NH | H16: On-site | I16: Part-time | J16: From $40/hr | K16: 83200 | M16: =IF(AND(K16="",L16=""),"",IF(L16="",K16,IF(K16="",L16,ROUND(AVERAGE(K16:L16),0)))) -> 83200 | N16: Indeed | O16: Apply ↗ | P16: 3 | Q16: Part-time accounting leadership; fits fractional/multi-client style | R16: Master | S16: Identified | AB16: =IF(T16="","",TODAY()-T16) | AC16: =IF(T16="","",IF(V16<>"","",IF(TODAY()-T16>=7,"DUE",""))) | AD16: =IF(T16="","",IF(AND(V16="",TODAY()-T16>=30),"GHOSTED","")) | AF16: =IF(E16="","",LOWER(E16&" | "&F16&" | "&G16)) -> breathe new hampshire | accounting manager | manchester, nh | AG16: =IF(AF16="","",IF(COUNTIF($AF$2:$AF$1000,AF16)>1,"DUP",""))
A17: 2026-10-016 | B17: 46318 | C17: 46308 | D17: Government | E17: Town of Sanbornton, NH | F17: Finance Coordinator | G17: Sanbornton, NH | H17: On-site | I17: Full-time | J17: $29.05–$36.26/hr | K17: 60424 | L17: 75421 | M17: =IF(AND(K17="",L17=""),"",IF(L17="",K17,IF(K17="",L17,ROUND(AVERAGE(K17:L17),0)))) -> 67923 | N17: Indeed | O17: Apply ↗ | P17: 3 | Q17: Municipal finance; stable role using reconciliations & reporting | R17: Master | S17: Identified | AB17: =IF(T17="","",TODAY()-T17) | AC17: =IF(T17="","",IF(V17<>"","",IF(TODAY()-T17>=7,"DUE",""))) | AD17: =IF(T17="","",IF(AND(V17="",TODAY()-T17>=30),"GHOSTED","")) | AF17: =IF(E17="","",LOWER(E17&" | "&F17&" | "&G17)) -> town of sanbornton, nh | finance coordinator | sanbornton, nh | AG17: =IF(AF17="","",IF(COUNTIF($AF$2:$AF$1000,AF17)>1,"DUP",""))
A18: 2026-10-017 | B18: 46318 | C18: 46232 | D18: Government | E18: New Hampshire Housing | F18: Senior Accountant, Section 8 & Federal Reporting | G18: Bedford, NH | H18: On-site | I18: Full-time | J18: $64,000–$78,000 | K18: 64000 | L18: 78000 | M18: =IF(AND(K18="",L18=""),"",IF(L18="",K18,IF(K18="",L18,ROUND(AVERAGE(K18:L18),0)))) -> 71000 | N18: Indeed | O18: Apply ↗ | P18: 3 | Q18: Senior accountant role; reporting-heavy, solid pay | R18: Master | S18: Identified | AB18: =IF(T18="","",TODAY()-T18) | AC18: =IF(T18="","",IF(V18<>"","",IF(TODAY()-T18>=7,"DUE",""))) | AD18: =IF(T18="","",IF(AND(V18="",TODAY()-T18>=30),"GHOSTED","")) | AF18: =IF(E18="","",LOWER(E18&" | "&F18&" | "&G18)) -> new hampshire housing | senior accountant, section 8 & federal reporting | bedford, nh | AG18: =IF(AF18="","",IF(COUNTIF($AF$2:$AF$1000,AF18)>1,"DUP",""))
A19: 2026-10-018 | B19: 46318 | C19: 46318 | D19: Accounting (corporate / industry) | E19: Associa | F19: Senior Accountant | G19: Bedford, NH | H19: On-site | I19: Full-time | J19: $80,000–$90,000 | K19: 80000 | L19: 90000 | M19: =IF(AND(K19="",L19=""),"",IF(L19="",K19,IF(K19="",L19,ROUND(AVERAGE(K19:L19),0)))) -> 85000 | N19: Indeed | O19: Apply ↗ | P19: 3 | Q19: Senior accountant with month-end close — aim-higher option | R19: Master | S19: Identified | AB19: =IF(T19="","",TODAY()-T19) | AC19: =IF(T19="","",IF(V19<>"","",IF(TODAY()-T19>=7,"DUE",""))) | AD19: =IF(T19="","",IF(AND(V19="",TODAY()-T19>=30),"GHOSTED","")) | AF19: =IF(E19="","",LOWER(E19&" | "&F19&" | "&G19)) -> associa | senior accountant | bedford, nh | AG19: =IF(AF19="","",IF(COUNTIF($AF$2:$AF$1000,AF19)>1,"DUP",""))
A20: 2026-10-019 | B20: 46318 | C20: 46318 | D20: Accounting (corporate / industry) | E20: Associa | F20: Client Accounting Specialist / Coordinator | G20: Bedford, NH | H20: On-site | I20: Full-time | J20: $20–$25/hr | K20: 41600 | L20: 52000 | M20: =IF(AND(K20="",L20=""),"",IF(L20="",K20,IF(K20="",L20,ROUND(AVERAGE(K20:L20),0)))) -> 46800 | N20: Indeed | O20: Apply ↗ | P20: 5 | Q20: Client-facing bookkeeping, like your recurring-client model | R20: Master | S20: Identified | AB20: =IF(T20="","",TODAY()-T20) | AC20: =IF(T20="","",IF(V20<>"","",IF(TODAY()-T20>=7,"DUE",""))) | AD20: =IF(T20="","",IF(AND(V20="",TODAY()-T20>=30),"GHOSTED","")) | AF20: =IF(E20="","",LOWER(E20&" | "&F20&" | "&G20)) -> associa | client accounting specialist / coordinator | bedford, nh | AG20: =IF(AF20="","",IF(COUNTIF($AF$2:$AF$1000,AF20)>1,"DUP",""))
A21: 2026-10-020 | B21: 46318 | C21: 46318 | D21: Accounting (corporate / industry) | E21: Wakefield Thermal Solutions | F21: Accounts Payable Coordinator | G21: Nashua, NH | H21: On-site | I21: N/A | J21: N/A | M21: =IF(AND(K21="",L21=""),"",IF(L21="",K21,IF(K21="",L21,ROUND(AVERAGE(K21:L21),0)))) | N21: Indeed | O21: Apply ↗ | P21: 3 | Q21: AP/transaction processing — core bookkeeping function | R21: Master | S21: Identified | AB21: =IF(T21="","",TODAY()-T21) | AC21: =IF(T21="","",IF(V21<>"","",IF(TODAY()-T21>=7,"DUE",""))) | AD21: =IF(T21="","",IF(AND(V21="",TODAY()-T21>=30),"GHOSTED","")) | AF21: =IF(E21="","",LOWER(E21&" | "&F21&" | "&G21)) -> wakefield thermal solutions | accounts payable coordinator | nashua, nh | AG21: =IF(AF21="","",IF(COUNTIF($AF$2:$AF$1000,AF21)>1,"DUP",""))
A22: 2026-10-021 | B22: 46318 | C22: 46301 | D22: Accounting (CPA firms) | E22: Business Cents | F22: Payroll Processor | G22: Manchester, NH | H22: On-site | I22: Full-time | J22: $25.63–$31.00/hr | K22: 53310 | L22: 64480 | M22: =IF(AND(K22="",L22=""),"",IF(L22="",K22,IF(K22="",L22,ROUND(AVERAGE(K22:L22),0)))) -> 58895 | N22: Indeed | O22: Apply ↗ | P22: 3 | Q22: Payroll at a Manchester bookkeeping firm; you list payroll review | R22: Master | S22: Identified | AB22: =IF(T22="","",TODAY()-T22) | AC22: =IF(T22="","",IF(V22<>"","",IF(TODAY()-T22>=7,"DUE",""))) | AD22: =IF(T22="","",IF(AND(V22="",TODAY()-T22>=30),"GHOSTED","")) | AF22: =IF(E22="","",LOWER(E22&" | "&F22&" | "&G22)) -> business cents | payroll processor | manchester, nh | AG22: =IF(AF22="","",IF(COUNTIF($AF$2:$AF$1000,AF22)>1,"DUP",""))
A23: 2026-10-022 | B23: 46318 | C23: 46307 | D23: Accounting (corporate / industry) | E23: Bronze Craft Corp | F23: Payroll and Accounts Receivable Specialist | G23: Nashua, NH | H23: On-site | I23: Full-time | J23: From $56,000 | K23: 56000 | M23: =IF(AND(K23="",L23=""),"",IF(L23="",K23,IF(K23="",L23,ROUND(AVERAGE(K23:L23),0)))) -> 56000 | N23: Indeed | O23: Apply ↗ | P23: 3 | Q23: AR + payroll role within commuting distance | R23: Master | S23: Identified | AB23: =IF(T23="","",TODAY()-T23) | AC23: =IF(T23="","",IF(V23<>"","",IF(TODAY()-T23>=7,"DUE",""))) | AD23: =IF(T23="","",IF(AND(V23="",TODAY()-T23>=30),"GHOSTED","")) | AF23: =IF(E23="","",LOWER(E23&" | "&F23&" | "&G23)) -> bronze craft corp | payroll and accounts receivable specialist | nashua, nh | AG23: =IF(AF23="","",IF(COUNTIF($AF$2:$AF$1000,AF23)>1,"DUP",""))
A24: 2026-10-023 | B24: 46318 | C24: 46297 | D24: Nonprofit | E24: Community Crossroads | F24: Accounting Coordinator | G24: Atkinson, NH | H24: On-site | I24: Full-time | J24: $44,540–$57,356 | K24: 44540 | L24: 57356 | M24: =IF(AND(K24="",L24=""),"",IF(L24="",K24,IF(K24="",L24,ROUND(AVERAGE(K24:L24),0)))) -> 50948 | N24: Indeed | O24: Apply ↗ | P24: 3 | Q24: Nonprofit accounting coordination; reconciliations & reporting | R24: Master | S24: Identified | AB24: =IF(T24="","",TODAY()-T24) | AC24: =IF(T24="","",IF(V24<>"","",IF(TODAY()-T24>=7,"DUE",""))) | AD24: =IF(T24="","",IF(AND(V24="",TODAY()-T24>=30),"GHOSTED","")) | AF24: =IF(E24="","",LOWER(E24&" | "&F24&" | "&G24)) -> community crossroads | accounting coordinator | atkinson, nh | AG24: =IF(AF24="","",IF(COUNTIF($AF$2:$AF$1000,AF24)>1,"DUP",""))
A25: 2026-10-024 | B25: 46318 | C25: 46307 | D25: Accounting (corporate / industry) | E25: KBW Financial Staffing | F25: Accountant II | G25: Portsmouth, NH | H25: On-site | I25: Permanent | J25: $70,000–$85,000 | K25: 70000 | L25: 85000 | M25: =IF(AND(K25="",L25=""),"",IF(L25="",K25,IF(K25="",L25,ROUND(AVERAGE(K25:L25),0)))) -> 77500 | N25: Indeed | O25: Apply ↗ | P25: 5 | Q25: Staffing firm placement for an experienced accountant — good pay | R25: Master | S25: Identified | AB25: =IF(T25="","",TODAY()-T25) | AC25: =IF(T25="","",IF(V25<>"","",IF(TODAY()-T25>=7,"DUE",""))) | AD25: =IF(T25="","",IF(AND(V25="",TODAY()-T25>=30),"GHOSTED","")) | AF25: =IF(E25="","",LOWER(E25&" | "&F25&" | "&G25)) -> kbw financial staffing | accountant ii | portsmouth, nh | AG25: =IF(AF25="","",IF(COUNTIF($AF$2:$AF$1000,AF25)>1,"DUP",""))
A26: 2026-10-025 | B26: 46318 | C26: 46239 | D26: Finance | E26: Service Credit Union | F26: Financial Accountant | G26: Portsmouth, NH | H26: On-site | I26: Full-time | J26: $94,959–$118,700 | K26: 94959 | L26: 118700 | M26: =IF(AND(K26="",L26=""),"",IF(L26="",K26,IF(K26="",L26,ROUND(AVERAGE(K26:L26),0)))) -> 106830 | N26: Indeed | O26: Apply ↗ | P26: 3 | Q26: Corporate accountant, strong salary; reach role with upside | R26: Master | S26: Identified | AB26: =IF(T26="","",TODAY()-T26) | AC26: =IF(T26="","",IF(V26<>"","",IF(TODAY()-T26>=7,"DUE",""))) | AD26: =IF(T26="","",IF(AND(V26="",TODAY()-T26>=30),"GHOSTED","")) | AF26: =IF(E26="","",LOWER(E26&" | "&F26&" | "&G26)) -> service credit union | financial accountant | portsmouth, nh | AG26: =IF(AF26="","",IF(COUNTIF($AF$2:$AF$1000,AF26)>1,"DUP",""))
A27: 2026-10-026 | B27: 46318 | C27: 46297 | D27: Accounting (CPA firms) | E27: Feature Solutions | F27: Tax Expert (CPA or EA) – Base + Commission | G27: Manchester, NH | H27: On-site | I27: Part-time | J27: $15–$40/hr | K27: 31200 | L27: 83200 | M27: =IF(AND(K27="",L27=""),"",IF(L27="",K27,IF(K27="",L27,ROUND(AVERAGE(K27:L27),0)))) -> 57200 | N27: Indeed | O27: Apply ↗ | P27: 3 | Q27: Leverages your 200+ returns of tax-prep experience | R27: Master | S27: Identified | AB27: =IF(T27="","",TODAY()-T27) | AC27: =IF(T27="","",IF(V27<>"","",IF(TODAY()-T27>=7,"DUE",""))) | AD27: =IF(T27="","",IF(AND(V27="",TODAY()-T27>=30),"GHOSTED","")) | AF27: =IF(E27="","",LOWER(E27&" | "&F27&" | "&G27)) -> feature solutions | tax expert (cpa or ea) – base + commission | manchester, nh | AG27: =IF(AF27="","",IF(COUNTIF($AF$2:$AF$1000,AF27)>1,"DUP",""))
A28: 2026-10-027 | B28: 46318 | C28: 46296 | D28: Tech / AI | E28: Intuit | F28: Tax Expert - Local | G28: Nashua, NH | H28: On-site | I28: N/A | J28: $27–$41/hr | K28: 56160 | L28: 85280 | M28: =IF(AND(K28="",L28=""),"",IF(L28="",K28,IF(K28="",L28,ROUND(AVERAGE(K28:L28),0)))) -> 70720 | N28: Indeed | O28: Apply ↗ | P28: 3 | Q28: Seasonal/flexible tax prep — matches your 1040/Sch C/S-corp work | R28: Master | S28: Identified | AB28: =IF(T28="","",TODAY()-T28) | AC28: =IF(T28="","",IF(V28<>"","",IF(TODAY()-T28>=7,"DUE",""))) | AD28: =IF(T28="","",IF(AND(V28="",TODAY()-T28>=30),"GHOSTED","")) | AF28: =IF(E28="","",LOWER(E28&" | "&F28&" | "&G28)) -> intuit | tax expert - local | nashua, nh | AG28: =IF(AF28="","",IF(COUNTIF($AF$2:$AF$1000,AF28)>1,"DUP",""))
A29: 2026-10-028 | B29: 46318 | C29: 46315 | D29: Accounting (corporate / industry) | E29: Pulsar Alarm Systems | F29: Certified Public Accountant | G29: Plaistow, NH | H29: On-site | I29: Full-time | J29: $100,000–$150,000 | K29: 100000 | L29: 150000 | M29: =IF(AND(K29="",L29=""),"",IF(L29="",K29,IF(K29="",L29,ROUND(AVERAGE(K29:L29),0)))) -> 125000 | N29: Indeed | O29: Apply ↗ | P29: 3 | Q29: Reach role for your CPA pathway (125/150 credits); top pay | R29: Master | S29: Identified | AB29: =IF(T29="","",TODAY()-T29) | AC29: =IF(T29="","",IF(V29<>"","",IF(TODAY()-T29>=7,"DUE",""))) | AD29: =IF(T29="","",IF(AND(V29="",TODAY()-T29>=30),"GHOSTED","")) | AF29: =IF(E29="","",LOWER(E29&" | "&F29&" | "&G29)) -> pulsar alarm systems | certified public accountant | plaistow, nh | AG29: =IF(AF29="","",IF(COUNTIF($AF$2:$AF$1000,AF29)>1,"DUP",""))
A30: 2026-10-029 | B30: 46318 | C30: 46307 | D30: Finance | E30: BAE Systems | F30: Senior Program Control Analyst, EAS Finance (Hybrid) | G30: Hudson, NH | H30: Hybrid | I30: Full-time | J30: $82,779–$140,723 | K30: 82779 | L30: 140723 | M30: =IF(AND(K30="",L30=""),"",IF(L30="",K30,IF(K30="",L30,ROUND(AVERAGE(K30:L30),0)))) -> 111751 | N30: Indeed | O30: Apply ↗ | P30: 3 | Q30: Program finance/analysis; hybrid, high ceiling | R30: Master | S30: Identified | AB30: =IF(T30="","",TODAY()-T30) | AC30: =IF(T30="","",IF(V30<>"","",IF(TODAY()-T30>=7,"DUE",""))) | AD30: =IF(T30="","",IF(AND(V30="",TODAY()-T30>=30),"GHOSTED","")) | AF30: =IF(E30="","",LOWER(E30&" | "&F30&" | "&G30)) -> bae systems | senior program control analyst, eas finance (hybrid) | hudson, nh | AG30: =IF(AF30="","",IF(COUNTIF($AF$2:$AF$1000,AF30)>1,"DUP",""))
A31: 2026-10-030 | B31: 46318 | C31: 46281 | D31: Accounting (CPA firms) | E31: Your Part-Time Controller, LLC | F31: Accountant (Fractional/Outsourced) | G31: Boston, MA | H31: On-site | I31: Part-time | J31: $70,000–$85,000 | K31: 70000 | L31: 85000 | M31: =IF(AND(K31="",L31=""),"",IF(L31="",K31,IF(K31="",L31,ROUND(AVERAGE(K31:L31),0)))) -> 77500 | N31: Indeed | O31: Apply ↗ | P31: 5 | Q31: Outsourced accounting — direct parallel to your fractional-CFO role | R31: Master | S31: Identified | AB31: =IF(T31="","",TODAY()-T31) | AC31: =IF(T31="","",IF(V31<>"","",IF(TODAY()-T31>=7,"DUE",""))) | AD31: =IF(T31="","",IF(AND(V31="",TODAY()-T31>=30),"GHOSTED","")) | AF31: =IF(E31="","",LOWER(E31&" | "&F31&" | "&G31)) -> your part-time controller, llc | accountant (fractional/outsourced) | boston, ma | AG31: =IF(AF31="","",IF(COUNTIF($AF$2:$AF$1000,AF31)>1,"DUP",""))
A32: 2026-10-031 | B32: 46318 | C32: 46274 | D32: Accounting (CPA firms) | E32: Roessel Joy | F32: Staff Accountant / Bookkeeper | G32: Danvers, MA | H32: On-site | I32: Full-time | J32: $30–$34/hr | K32: 62400 | L32: 70720 | M32: =IF(AND(K32="",L32=""),"",IF(L32="",K32,IF(K32="",L32,ROUND(AVERAGE(K32:L32),0)))) -> 66560 | N32: Indeed | O32: Apply ↗ | P32: 5 | Q32: Hybrid staff accountant + bookkeeper; exactly your profile | R32: Master | S32: Identified | AB32: =IF(T32="","",TODAY()-T32) | AC32: =IF(T32="","",IF(V32<>"","",IF(TODAY()-T32>=7,"DUE",""))) | AD32: =IF(T32="","",IF(AND(V32="",TODAY()-T32>=30),"GHOSTED","")) | AF32: =IF(E32="","",LOWER(E32&" | "&F32&" | "&G32)) -> roessel joy | staff accountant / bookkeeper | danvers, ma | AG32: =IF(AF32="","",IF(COUNTIF($AF$2:$AF$1000,AF32)>1,"DUP",""))
A33: 2026-10-032 | B33: 46318 | C33: 46316 | D33: Accounting (corporate / industry) | E33: LVR Corporation | F33: Office Administrator / Bookkeeper | G33: Peabody, MA | H33: On-site | I33: Part-time | J33: $25–$35/hr | K33: 52000 | L33: 72800 | M33: =IF(AND(K33="",L33=""),"",IF(L33="",K33,IF(K33="",L33,ROUND(AVERAGE(K33:L33),0)))) -> 62400 | N33: Indeed | O33: Apply ↗ | P33: 5 | Q33: Small-business full-charge bookkeeping | R33: Master | S33: Identified | AB33: =IF(T33="","",TODAY()-T33) | AC33: =IF(T33="","",IF(V33<>"","",IF(TODAY()-T33>=7,"DUE",""))) | AD33: =IF(T33="","",IF(AND(V33="",TODAY()-T33>=30),"GHOSTED","")) | AF33: =IF(E33="","",LOWER(E33&" | "&F33&" | "&G33)) -> lvr corporation | office administrator / bookkeeper | peabody, ma | AG33: =IF(AF33="","",IF(COUNTIF($AF$2:$AF$1000,AF33)>1,"DUP",""))
A34: 2026-10-033 | B34: 46318 | C34: 46292 | D34: Accounting (CPA firms) | E34: Drewnick Bookkeeping LLC | F34: Bookkeeper | G34: Tewksbury, MA | H34: On-site | I34: Part-time | J34: $22–$32/hr | K34: 45760 | L34: 66560 | M34: =IF(AND(K34="",L34=""),"",IF(L34="",K34,IF(K34="",L34,ROUND(AVERAGE(K34:L34),0)))) -> 56160 | N34: Indeed | O34: Apply ↗ | P34: 5 | Q34: Bookkeeping firm — multi-client QBO work like yours | R34: Master | S34: Identified | AB34: =IF(T34="","",TODAY()-T34) | AC34: =IF(T34="","",IF(V34<>"","",IF(TODAY()-T34>=7,"DUE",""))) | AD34: =IF(T34="","",IF(AND(V34="",TODAY()-T34>=30),"GHOSTED","")) | AF34: =IF(E34="","",LOWER(E34&" | "&F34&" | "&G34)) -> drewnick bookkeeping llc | bookkeeper | tewksbury, ma | AG34: =IF(AF34="","",IF(COUNTIF($AF$2:$AF$1000,AF34)>1,"DUP",""))
A35: 2026-10-034 | B35: 46318 | C35: 46318 | D35: Accounting (corporate / industry) | E35: Kelly Auto Group | F35: Auto Dealership Accountant / Bookkeeper | G35: Lynnfield, MA | H35: On-site | I35: Full-time | J35: $23–$28/hr | K35: 47840 | L35: 58240 | M35: =IF(AND(K35="",L35=""),"",IF(L35="",K35,IF(K35="",L35,ROUND(AVERAGE(K35:L35),0)))) -> 53040 | N35: Indeed | O35: Apply ↗ | P35: 3 | Q35: High-volume transaction reconciliation; fresh posting | R35: Master | S35: Identified | AB35: =IF(T35="","",TODAY()-T35) | AC35: =IF(T35="","",IF(V35<>"","",IF(TODAY()-T35>=7,"DUE",""))) | AD35: =IF(T35="","",IF(AND(V35="",TODAY()-T35>=30),"GHOSTED","")) | AF35: =IF(E35="","",LOWER(E35&" | "&F35&" | "&G35)) -> kelly auto group | auto dealership accountant / bookkeeper | lynnfield, ma | AG35: =IF(AF35="","",IF(COUNTIF($AF$2:$AF$1000,AF35)>1,"DUP",""))
... A39: 2026-10-038 | B39: 46318 | C39: 46294 | D39: Accounting (corporate / industry) | E39: Straumann Group | F39: Cost Accountant (Manufacturing) | G39: Andover, MA | H39: On-site | I39: Full-time | J39: $77,000–$94,000 | K39: 77000 | L39: 94000 | M39: =IF(AND(K39="",L39=""),"",IF(L39="",K39,IF(K39="",L39,ROUND(AVERAGE(K39:L39),0)))) -> 85500 | N39: Indeed | O39: Apply ↗ | P39: 3 | Q39: Cost/unit-economics analysis — maps to your SKU-level work | R39: Master | S39: Identified | AB39: =IF(T39="","",TODAY()-T39) | AC39: =IF(T39="","",IF(V39<>"","",IF(TODAY()-T39>=7,"DUE",""))) | AD39: =IF(T39="","",IF(AND(V39="",TODAY()-T39>=30),"GHOSTED","")) | AF39: =IF(E39="","",LOWER(E39&" | "&F39&" | "&G39)) -> straumann group | cost accountant (manufacturing) | andover, ma | AG39: =IF(AF39="","",IF(COUNTIF($AF$2:$AF$1000,AF39)>1,"DUP",""))
A40: 2026-10-039 | B40: 46318 | C40: 46267 | D40: Accounting (CPA firms) | E40: Donovan, Sullivan & Ryan | F40: Tax Accountant – Entry Level | G40: Westwood, MA | H40: On-site | I40: Full-time | J40: From $70,000 | K40: 70000 | M40: =IF(AND(K40="",L40=""),"",IF(L40="",K40,IF(K40="",L40,ROUND(AVERAGE(K40:L40),0)))) -> 70000 | N40: Indeed | O40: Apply ↗ | P40: 5 | Q40: Entry CPA-firm tax role; uses your tax-prep background | R40: Master | S40: Identified | AB40: =IF(T40="","",TODAY()-T40) | AC40: =IF(T40="","",IF(V40<>"","",IF(TODAY()-T40>=7,"DUE",""))) | AD40: =IF(T40="","",IF(AND(V40="",TODAY()-T40>=30),"GHOSTED","")) | AF40: =IF(E40="","",LOWER(E40&" | "&F40&" | "&G40)) -> donovan, sullivan & ryan | tax accountant – entry level | westwood, ma | AG40: =IF(AF40="","",IF(COUNTIF($AF$2:$AF$1000,AF40)>1,"DUP",""))
A41: 2026-10-040 | B41: 46318 | C41: 46259 | D41: Accounting (CPA firms) | E41: David Miller CPA LLC | F41: Tax Accountant | G41: Cambridge, MA | H41: On-site | I41: Full-time | J41: $80,000–$90,000 | K41: 80000 | L41: 90000 | M41: =IF(AND(K41="",L41=""),"",IF(L41="",K41,IF(K41="",L41,ROUND(AVERAGE(K41:L41),0)))) -> 85000 | N41: Indeed | O41: Apply ↗ | P41: 3 | Q41: CPA-firm tax accountant; strong pay for your tax experience | R41: Master | S41: Identified | AB41: =IF(T41="","",TODAY()-T41) | AC41: =IF(T41="","",IF(V41<>"","",IF(TODAY()-T41>=7,"DUE",""))) | AD41: =IF(T41="","",IF(AND(V41="",TODAY()-T41>=30),"GHOSTED","")) | AF41: =IF(E41="","",LOWER(E41&" | "&F41&" | "&G41)) -> david miller cpa llc | tax accountant | cambridge, ma | AG41: =IF(AF41="","",IF(COUNTIF($AF$2:$AF$1000,AF41)>1,"DUP",""))
A42: 2026-10-041 | B42: 46318 | C42: 46252 | D42: Accounting (corporate / industry) | E42: Robert Reiser & Company | F42: Senior Accountant | G42: Canton, MA | H42: On-site | I42: Full-time | J42: $85,000–$120,000 | K42: 85000 | L42: 120000 | M42: =IF(AND(K42="",L42=""),"",IF(L42="",K42,IF(K42="",L42,ROUND(AVERAGE(K42:L42),0)))) -> 102500 | N42: Indeed | O42: Apply ↗ | P42: 3 | Q42: Senior accountant, high pay — reach role with full-cycle duties | R42: Master | S42: Identified | AB42: =IF(T42="","",TODAY()-T42) | AC42: =IF(T42="","",IF(V42<>"","",IF(TODAY()-T42>=7,"DUE",""))) | AD42: =IF(T42="","",IF(AND(V42="",TODAY()-T42>=30),"GHOSTED","")) | AF42: =IF(E42="","",LOWER(E42&" | "&F42&" | "&G42)) -> robert reiser & company | senior accountant | canton, ma | AG42: =IF(AF42="","",IF(COUNTIF($AF$2:$AF$1000,AF42)>1,"DUP",""))
A43: 2026-10-042 | B43: 46318 | C43: 46294 | D43: Finance | E43: New Balance | F43: Retail Financial Analyst | G43: Lawrence, MA | H43: On-site | I43: Full-time | J43: $70,600–$110,400 | K43: 70600 | L43: 110400 | M43: =IF(AND(K43="",L43=""),"",IF(L43="",K43,IF(K43="",L43,ROUND(AVERAGE(K43:L43),0)))) -> 90500 | N43: Indeed | O43: Apply ↗ | P43: 5 | Q43: Financial analysis at a major brand; your e-commerce/retail angle | R43: Master | S43: Identified | AB43: =IF(T43="","",TODAY()-T43) | AC43: =IF(T43="","",IF(V43<>"","",IF(TODAY()-T43>=7,"DUE",""))) | AD43: =IF(T43="","",IF(AND(V43="",TODAY()-T43>=30),"GHOSTED","")) | AF43: =IF(E43="","",LOWER(E43&" | "&F43&" | "&G43)) -> new balance | retail financial analyst | lawrence, ma | AG43: =IF(AF43="","",IF(COUNTIF($AF$2:$AF$1000,AF43)>1,"DUP",""))
...

Sheet Pipeline
A1: Job ID | B1: Company | C1: Title | D1: Fit | E1: Stage | F1: Applied | G1: Contacted | H1: Responded | I1: Interview | J1: Offer | K1: Rejected | L1: Stopped At | M1: Days Since Applied | N1: Next Action
A2: =IF(Jobs!$A2="","",Jobs!$A2) -> 2026-10-001 | B2: =IF(Jobs!$A2="","",Jobs!$E2) -> Feature Solutions | C2: =IF(Jobs!$A2="","",Jobs!$F2) -> Bookkeeper – Part-Time (QuickBooks Online) | D2: =IF(Jobs!$A2="","",Jobs!$P2) -> 5 | E2: =IF(Jobs!$A2="","",Jobs!$S2) -> Identified | F2: =IF(Jobs!$A2="","",Jobs!$T2) -> 0 | G2: =IF(Jobs!$A2="","",Jobs!$U2) -> 0 | H2: =IF(Jobs!$A2="","",Jobs!$V2) -> 0 | I2: =IF(Jobs!$A2="","",Jobs!$X2) -> 0 | J2: =IF(Jobs!$A2="","",Jobs!$Y2) -> 0 | K2: =IF(Jobs!$A2="","",Jobs!$Z2) -> 0 | L2: =IF(Jobs!$A2="","",IF(Jobs!$Z2<>"","Rejected",IF(Jobs!$Y2<>"","Offer",IF(Jobs!$X2<>"","Interview",IF(Jobs!$V2<>"","Responded",IF(Jobs!$U2<>"","Contacted",IF(Jobs!$T2<>"","Applied","Not applied yet"))))))) -> Not applied yet | M2: =IF(Jobs!$A2="","",Jobs!$AB2) | N2: =IF(Jobs!$A2="","",Jobs!$AA2) -> 0
A3: =IF(Jobs!$A3="","",Jobs!$A3) -> 2026-10-002 | B3: =IF(Jobs!$A3="","",Jobs!$E3) -> Business Cents | C3: =IF(Jobs!$A3="","",Jobs!$F3) -> Senior Bookkeeper | D3: =IF(Jobs!$A3="","",Jobs!$P3) -> 5 | E3: =IF(Jobs!$A3="","",Jobs!$S3) -> Identified | F3: =IF(Jobs!$A3="","",Jobs!$T3) -> 0 | G3: =IF(Jobs!$A3="","",Jobs!$U3) -> 0 | H3: =IF(Jobs!$A3="","",Jobs!$V3) -> 0 | I3: =IF(Jobs!$A3="","",Jobs!$X3) -> 0 | J3: =IF(Jobs!$A3="","",Jobs!$Y3) -> 0 | K3: =IF(Jobs!$A3="","",Jobs!$Z3) -> 0 | L3: =IF(Jobs!$A3="","",IF(Jobs!$Z3<>"","Rejected",IF(Jobs!$Y3<>"","Offer",IF(Jobs!$X3<>"","Interview",IF(Jobs!$V3<>"","Responded",IF(Jobs!$U3<>"","Contacted",IF(Jobs!$T3<>"","Applied","Not applied yet"))))))) -> Not applied yet | M3: =IF(Jobs!$A3="","",Jobs!$AB3) | N3: =IF(Jobs!$A3="","",Jobs!$AA3) -> 0
A4: =IF(Jobs!$A4="","",Jobs!$A4) -> 2026-10-003 | B4: =IF(Jobs!$A4="","",Jobs!$E4) -> 3 Lions Logistics | C4: =IF(Jobs!$A4="","",Jobs!$F4) -> Bookkeeper/ Staff Accountant | D4: =IF(Jobs!$A4="","",Jobs!$P4) -> 5 | E4: =IF(Jobs!$A4="","",Jobs!$S4) -> Identified | F4: =IF(Jobs!$A4="","",Jobs!$T4) -> 0 | G4: =IF(Jobs!$A4="","",Jobs!$U4) -> 0 | H4: =IF(Jobs!$A4="","",Jobs!$V4) -> 0 | I4: =IF(Jobs!$A4="","",Jobs!$X4) -> 0 | J4: =IF(Jobs!$A4="","",Jobs!$Y4) -> 0 | K4: =IF(Jobs!$A4="","",Jobs!$Z4) -> 0 | L4: =IF(Jobs!$A4="","",IF(Jobs!$Z4<>"","Rejected",IF(Jobs!$Y4<>"","Offer",IF(Jobs!$X4<>"","Interview",IF(Jobs!$V4<>"","Responded",IF(Jobs!$U4<>"","Contacted",IF(Jobs!$T4<>"","Applied","Not applied yet"))))))) -> Not applied yet | M4: =IF(Jobs!$A4="","",Jobs!$AB4) | N4: =IF(Jobs!$A4="","",Jobs!$AA4) -> 0
A5: =IF(Jobs!$A5="","",Jobs!$A5) -> 2026-10-004 | B5: =IF(Jobs!$A5="","",Jobs!$E5) -> 3 Lions Logistics | C5: =IF(Jobs!$A5="","",Jobs!$F5) -> Junior Accountant | D5: =IF(Jobs!$A5="","",Jobs!$P5) -> 5 | E5: =IF(Jobs!$A5="","",Jobs!$S5) -> Identified | F5: =IF(Jobs!$A5="","",Jobs!$T5) -> 0 | G5: =IF(Jobs!$A5="","",Jobs!$U5) -> 0 | H5: =IF(Jobs!$A5="","",Jobs!$V5) -> 0 | I5: =IF(Jobs!$A5="","",Jobs!$X5) -> 0 | J5: =IF(Jobs!$A5="","",Jobs!$Y5) -> 0 | K5: =IF(Jobs!$A5="","",Jobs!$Z5) -> 0 | L5: =IF(Jobs!$A5="","",IF(Jobs!$Z5<>"","Rejected",IF(Jobs!$Y5<>"","Offer",IF(Jobs!$X5<>"","Interview",IF(Jobs!$V5<>"","Responded",IF(Jobs!$U5<>"","Contacted",IF(Jobs!$T5<>"","Applied","Not applied yet"))))))) -> Not applied yet | M5: =IF(Jobs!$A5="","",Jobs!$AB5) | N5: =IF(Jobs!$A5="","",Jobs!$AA5) -> 0
A6: =IF(Jobs!$A6="","",Jobs!$A6) -> 2026-10-005 | B6: =IF(Jobs!$A6="","",Jobs!$E6) -> Scott Electronics, Inc. | C6: =IF(Jobs!$A6="","",Jobs!$F6) -> Staff Accountant | D6: =IF(Jobs!$A6="","",Jobs!$P6) -> 5 | E6: =IF(Jobs!$A6="","",Jobs!$S6) -> Identified | F6: =IF(Jobs!$A6="","",Jobs!$T6) -> 0 | G6: =IF(Jobs!$A6="","",Jobs!$U6) -> 0 | H6: =IF(Jobs!$A6="","",Jobs!$V6) -> 0 | I6: =IF(Jobs!$A6="","",Jobs!$X6) -> 0 | J6: =IF(Jobs!$A6="","",Jobs!$Y6) -> 0 | K6: =IF(Jobs!$A6="","",Jobs!$Z6) -> 0 | L6: =IF(Jobs!$A6="","",IF(Jobs!$Z6<>"","Rejected",IF(Jobs!$Y6<>"","Offer",IF(Jobs!$X6<>"","Interview",IF(Jobs!$V6<>"","Responded",IF(Jobs!$U6<>"","Contacted",IF(Jobs!$T6<>"","Applied","Not applied yet"))))))) -> Not applied yet | M6: =IF(Jobs!$A6="","",Jobs!$AB6) | N6: =IF(Jobs!$A6="","",Jobs!$AA6) -> 0
A7: =IF(Jobs!$A7="","",Jobs!$A7) -> 2026-10-006 | B7: =IF(Jobs!$A7="","",Jobs!$E7) -> Paul Davis Restoration | C7: =IF(Jobs!$A7="","",Jobs!$F7) -> Reconstruction Job Cost Accountant | D7: =IF(Jobs!$A7="","",Jobs!$P7) -> 3 | E7: =IF(Jobs!$A7="","",Jobs!$S7) -> Identified | F7: =IF(Jobs!$A7="","",Jobs!$T7) -> 0 | G7: =IF(Jobs!$A7="","",Jobs!$U7) -> 0 | H7: =IF(Jobs!$A7="","",Jobs!$V7) -> 0 | I7: =IF(Jobs!$A7="","",Jobs!$X7) -> 0 | J7: =IF(Jobs!$A7="","",Jobs!$Y7) -> 0 | K7: =IF(Jobs!$A7="","",Jobs!$Z7) -> 0 | L7: =IF(Jobs!$A7="","",IF(Jobs!$Z7<>"","Rejected",IF(Jobs!$Y7<>"","Offer",IF(Jobs!$X7<>"","Interview",IF(Jobs!$V7<>"","Responded",IF(Jobs!$U7<>"","Contacted",IF(Jobs!$T7<>"","Applied","Not applied yet"))))))) -> Not applied yet | M7: =IF(Jobs!$A7="","",Jobs!$AB7) | N7: =IF(Jobs!$A7="","",Jobs!$AA7) -> 0
A8: =IF(Jobs!$A8="","",Jobs!$A8) -> 2026-10-007 | B8: =IF(Jobs!$A8="","",Jobs!$E8) -> Goedecke Flooring & Design | C8: =IF(Jobs!$A8="","",Jobs!$F8) -> Bookkeeper & HR Administrator | D8: =IF(Jobs!$A8="","",Jobs!$P8) -> 5 | E8: =IF(Jobs!$A8="","",Jobs!$S8) -> Identified | F8: =IF(Jobs!$A8="","",Jobs!$T8) -> 0 | G8: =IF(Jobs!$A8="","",Jobs!$U8) -> 0 | H8: =IF(Jobs!$A8="","",Jobs!$V8) -> 0 | I8: =IF(Jobs!$A8="","",Jobs!$X8) -> 0 | J8: =IF(Jobs!$A8="","",Jobs!$Y8) -> 0 | K8: =IF(Jobs!$A8="","",Jobs!$Z8) -> 0 | L8: =IF(Jobs!$A8="","",IF(Jobs!$Z8<>"","Rejected",IF(Jobs!$Y8<>"","Offer",IF(Jobs!$X8<>"","Interview",IF(Jobs!$V8<>"","Responded",IF(Jobs!$U8<>"","Contacted",IF(Jobs!$T8<>"","Applied","Not applied yet"))))))) -> Not applied yet | M8: =IF(Jobs!$A8="","",Jobs!$AB8) | N8: =IF(Jobs!$A8="","",Jobs!$AA8) -> 0
A9: =IF(Jobs!$A9="","",Jobs!$A9) -> 2026-10-008 | B9: =IF(Jobs!$A9="","",Jobs!$E9) -> Generator Pro / Spa Guy | C9: =IF(Jobs!$A9="","",Jobs!$F9) -> Assistant Bookkeeper / Office Assistant | D9: =IF(Jobs!$A9="","",Jobs!$P9) -> 3 | E9: =IF(Jobs!$A9="","",Jobs!$S9) -> Identified | F9: =IF(Jobs!$A9="","",Jobs!$T9) -> 0 | G9: =IF(Jobs!$A9="","",Jobs!$U9) -> 0 | H9: =IF(Jobs!$A9="","",Jobs!$V9) -> 0 | I9: =IF(Jobs!$A9="","",Jobs!$X9) -> 0 | J9: =IF(Jobs!$A9="","",Jobs!$Y9) -> 0 | K9: =IF(Jobs!$A9="","",Jobs!$Z9) -> 0 | L9: =IF(Jobs!$A9="","",IF(Jobs!$Z9<>"","Rejected",IF(Jobs!$Y9<>"","Offer",IF(Jobs!$X9<>"","Interview",IF(Jobs!$V9<>"","Responded",IF(Jobs!$U9<>"","Contacted",IF(Jobs!$T9<>"","Applied","Not applied yet"))))))) -> Not applied yet | M9: =IF(Jobs!$A9="","",Jobs!$AB9) | N9: =IF(Jobs!$A9="","",Jobs!$AA9) -> 0
A10: =IF(Jobs!$A10="","",Jobs!$A10) -> 2026-10-009 | B10: =IF(Jobs!$A10="","",Jobs!$E10) -> Stephens-Marquis Associates | C10: =IF(Jobs!$A10="","",Jobs!$F10) -> Accounting Administrator | D10: =IF(Jobs!$A10="","",Jobs!$P10) -> 5 | E10: =IF(Jobs!$A10="","",Jobs!$S10) -> Identified | F10: =IF(Jobs!$A10="","",Jobs!$T10) -> 0 | G10: =IF(Jobs!$A10="","",Jobs!$U10) -> 0 | H10: =IF(Jobs!$A10="","",Jobs!$V10) -> 0 | I10: =IF(Jobs!$A10="","",Jobs!$X10) -> 0 | J10: =IF(Jobs!$A10="","",Jobs!$Y10) -> 0 | K10: =IF(Jobs!$A10="","",Jobs!$Z10) -> 0 | L10: =IF(Jobs!$A10="","",IF(Jobs!$Z10<>"","Rejected",IF(Jobs!$Y10<>"","Offer",IF(Jobs!$X10<>"","Interview",IF(Jobs!$V10<>"","Responded",IF(Jobs!$U10<>"","Contacted",IF(Jobs!$T10<>"","Applied","Not applied yet"))))))) -> Not applied yet | M10: =IF(Jobs!$A10="","",Jobs!$AB10) | N10: =IF(Jobs!$A10="","",Jobs!$AA10) -> 0
A11: =IF(Jobs!$A11="","",Jobs!$A11) -> 2026-10-010 | B11: =IF(Jobs!$A11="","",Jobs!$E11) -> JLS Mailing Services | C11: =IF(Jobs!$A11="","",Jobs!$F11) -> Bookkeeper/Accounts Administrator | D11: =IF(Jobs!$A11="","",Jobs!$P11) -> 5 | E11: =IF(Jobs!$A11="","",Jobs!$S11) -> Identified | F11: =IF(Jobs!$A11="","",Jobs!$T11) -> 0 | G11: =IF(Jobs!$A11="","",Jobs!$U11) -> 0 | H11: =IF(Jobs!$A11="","",Jobs!$V11) -> 0 | I11: =IF(Jobs!$A11="","",Jobs!$X11) -> 0 | J11: =IF(Jobs!$A11="","",Jobs!$Y11) -> 0 | K11: =IF(Jobs!$A11="","",Jobs!$Z11) -> 0 | L11: =IF(Jobs!$A11="","",IF(Jobs!$Z11<>"","Rejected",IF(Jobs!$Y11<>"","Offer",IF(Jobs!$X11<>"","Interview",IF(Jobs!$V11<>"","Responded",IF(Jobs!$U11<>"","Contacted",IF(Jobs!$T11<>"","Applied","Not applied yet"))))))) -> Not applied yet | M11: =IF(Jobs!$A11="","",Jobs!$AB11) | N11: =IF(Jobs!$A11="","",Jobs!$AA11) -> 0
A12: =IF(Jobs!$A12="","",Jobs!$A12) -> 2026-10-011 | B12: =IF(Jobs!$A12="","",Jobs!$E12) -> Ford of Londonderry | C12: =IF(Jobs!$A12="","",Jobs!$F12) -> Accounting/Administration | D12: =IF(Jobs!$A12="","",Jobs!$P12) -> 3 | E12: =IF(Jobs!$A12="","",Jobs!$S12) -> Identified | F12: =IF(Jobs!$A12="","",Jobs!$T12) -> 0 | G12: =IF(Jobs!$A12="","",Jobs!$U12) -> 0 | H12: =IF(Jobs!$A12="","",Jobs!$V12) -> 0 | I12: =IF(Jobs!$A12="","",Jobs!$X12) -> 0 | J12: =IF(Jobs!$A12="","",Jobs!$Y12) -> 0 | K12: =IF(Jobs!$A12="","",Jobs!$Z12) -> 0 | L12: =IF(Jobs!$A12="","",IF(Jobs!$Z12<>"","Rejected",IF(Jobs!$Y12<>"","Offer",IF(Jobs!$X12<>"","Interview",IF(Jobs!$V12<>"","Responded",IF(Jobs!$U12<>"","Contacted",IF(Jobs!$T12<>"","Applied","Not applied yet"))))))) -> Not applied yet | M12: =IF(Jobs!$A12="","",Jobs!$AB12) | N12: =IF(Jobs!$A12="","",Jobs!$AA12) -> 0
A13: =IF(Jobs!$A13="","",Jobs!$A13) -> 2026-10-012 | B13: =IF(Jobs!$A13="","",Jobs!$E13) -> Pine Haven Boys Center | C13: =IF(Jobs!$A13="","",Jobs!$F13) -> Financial Operations Specialist | D13: =IF(Jobs!$A13="","",Jobs!$P13) -> 5 | E13: =IF(Jobs!$A13="","",Jobs!$S13) -> Identified | F13: =IF(Jobs!$A13="","",Jobs!$T13) -> 0 | G13: =IF(Jobs!$A13="","",Jobs!$U13) -> 0 | H13: =IF(Jobs!$A13="","",Jobs!$V13) -> 0 | I13: =IF(Jobs!$A13="","",Jobs!$X13) -> 0 | J13: =IF(Jobs!$A13="","",Jobs!$Y13) -> 0 | K13: =IF(Jobs!$A13="","",Jobs!$Z13) -> 0 | L13: =IF(Jobs!$A13="","",IF(Jobs!$Z13<>"","Rejected",IF(Jobs!$Y13<>"","Offer",IF(Jobs!$X13<>"","Interview",IF(Jobs!$V13<>"","Responded",IF(Jobs!$U13<>"","Contacted",IF(Jobs!$T13<>"","Applied","Not applied yet"))))))) -> Not applied yet | M13: =IF(Jobs!$A13="","",Jobs!$AB13) | N13: =IF(Jobs!$A13="","",Jobs!$AA13) -> 0
... A201: =IF(Jobs!$A201="","",Jobs!$A201) | B201: =IF(Jobs!$A201="","",Jobs!$E201) | C201: =IF(Jobs!$A201="","",Jobs!$F201) | D201: =IF(Jobs!$A201="","",Jobs!$P201) | E201: =IF(Jobs!$A201="","",Jobs!$S201) | F201: =IF(Jobs!$A201="","",Jobs!$T201) | G201: =IF(Jobs!$A201="","",Jobs!$U201) | H201: =IF(Jobs!$A201="","",Jobs!$V201) | I201: =IF(Jobs!$A201="","",Jobs!$X201) | J201: =IF(Jobs!$A201="","",Jobs!$Y201) | K201: =IF(Jobs!$A201="","",Jobs!$Z201) | L201: =IF(Jobs!$A201="","",IF(Jobs!$Z201<>"","Rejected",IF(Jobs!$Y201<>"","Offer",IF(Jobs!$X201<>"","Interview",IF(Jobs!$V201<>"","Responded",IF(Jobs!$U201<>"","Contacted",IF(Jobs!$T201<>"","Applied","Not applied yet"))))))) | M201: =IF(Jobs!$A201="","",Jobs!$AB201) | N201: =IF(Jobs!$A201="","",Jobs!$AA201)

Sheet Activity Log
A1: ACTIVITY LOG — every call, email, and follow-up. One action per row (keeps history even when a status changes).
A2: Date | B2: Job ID | C2: Company (auto) | D2: Action | E2: Notes | F2: Next Step | G2: Next Action Date
A3: 46318 | B3: 2026-10-001 | C3: =IFERROR(INDEX(Jobs!$E:$E,MATCH($B3,Jobs!$A:$A,0)),"") -> Feature Solutions | D3: Found / saved | E3: Sourced via Indeed; saved to tracker. Example row — overwrite or delete. | F3: Apply | G3: 46321
C4: =IFERROR(INDEX(Jobs!$E:$E,MATCH($B4,Jobs!$A:$A,0)),"")
C5: =IFERROR(INDEX(Jobs!$E:$E,MATCH($B5,Jobs!$A:$A,0)),"")
C6: =IFERROR(INDEX(Jobs!$E:$E,MATCH($B6,Jobs!$A:$A,0)),"")
C7: =IFERROR(INDEX(Jobs!$E:$E,MATCH($B7,Jobs!$A:$A,0)),"")
C8: =IFERROR(INDEX(Jobs!$E:$E,MATCH($B8,Jobs!$A:$A,0)),"")
C9: =IFERROR(INDEX(Jobs!$E:$E,MATCH($B9,Jobs!$A:$A,0)),"")
C10: =IFERROR(INDEX(Jobs!$E:$E,MATCH($B10,Jobs!$A:$A,0)),"")
C11: =IFERROR(INDEX(Jobs!$E:$E,MATCH($B11,Jobs!$A:$A,0)),"")
C12: =IFERROR(INDEX(Jobs!$E:$E,MATCH($B12,Jobs!$A:$A,0)),"")
C13: =IFERROR(INDEX(Jobs!$E:$E,MATCH($B13,Jobs!$A:$A,0)),"")
C14: =IFERROR(INDEX(Jobs!$E:$E,MATCH($B14,Jobs!$A:$A,0)),"")
C15: =IFERROR(INDEX(Jobs!$E:$E,MATCH($B15,Jobs!$A:$A,0)),"")
... C250: =IFERROR(INDEX(Jobs!$E:$E,MATCH($B250,Jobs!$A:$A,0)),"")

Sheet Contacts
A1: CONTACTS — people you reached out to (recruiters, hiring managers, referrals).
A2: Name | B2: Company | C2: Role / Title | D2: Job ID | E2: Email / Phone | F2: Method | G2: Date Contacted | H2: Response | I2: Next Step | J2: Next Action Date | K2: Notes
A3: — example — | B3: Business Cents | C3: Hiring Manager | D3: 2026-10-002 | F3: LinkedIn | G3: 46319 | H3: No response yet | I3: Follow up | J3: 46326 | K3: Example row — overwrite or delete.

Sheet SWOT
A1: SWOT ANALYSIS — David St. Julus
A2: Grounded in the résumé (Strengths/Weaknesses) and the Oct 2026 NH/MA job sheet (Opportunities/Threats). Each point cites its evidence — no invented metrics.
A4: STRENGTHS | D4: WEAKNESSES
A5: Point | B5: Evidence | D5: Point | E5: Evidence
A6: • Full-cycle bookkeeping & month-end close across multiple concurrent clients. | B6: Résumé — System Built Financials: “full-cycle bookkeeping and month-end close for four recurring small-business clients.” | D6: • CPA not yet licensed — 125 of 150 credits; exam/coursework still ahead. | E6: Résumé — Education: “CPA pathway: 125 of 150 required credits completed; additional coursework planned for 2027.”
A7: • Proven at cleaning up and standardizing disorganized books into tax-ready records. | B7: Résumé — System Built Financials: “Clean up and standardize disorganized financial records… tax-preparation readiness.” | D7: • Experience concentrated in small-business / self-employment, not large-corporate teams. | E7: Résumé — Experience: founder/fractional roles with small-business clients; no large-team corporate role listed.
A8: • FP&A depth: KPI dashboards, variance, budgeting & cash-flow analysis. | B8: Résumé — Summary & Skills: “recurring KPI dashboards”; “P&L analysis… variance analysis, budgeting and forecasting support.” | D8: • Limited tenure in formal employed accounting titles (mostly founder/fractional since 2022). | E8: Résumé — Experience dates: System Built (2026– ), Move-U fractional (2025–26), Julus Essentials (2022–25).
A9: • Demonstrated financial impact — surfaced ~$50K/yr in billing leakage. | B9: Résumé — Move-U Moving Services: “Identified approximately $50,000 in estimated annual billing leakage.” | D9: • Secondary tools stated as “experience with,” not primary proficiency. | E9: Résumé — Skills: “experience with Sage and Power BI” vs. “Proficient in QuickBooks Online and Excel.”
A10: • High-volume reconciliation experience at scale. | B10: Résumé — Julus Essentials “Reconciled 10,000+ transactions”; Move-U “100+ transactions and ~$60,000 in deposits each month.” | D10: • No public-accounting / audit-firm background on the résumé. | E10: Résumé — Experience: no CPA-firm or audit employer listed (relevant for CPA-firm postings).
A11: • Tax-prep depth: 200+ returns (1040, Sch C, S-corp) over four seasons. | B11: Résumé — Jean Tax Services: “Prepared 50+… returns per season (200+ across four seasons).”
A12: • Tech/automation edge: QBO, advanced Excel (PivotTables, Power Query, macros), custom GPTs. | B12: Résumé — Skills & System Built: “Excel (PivotTables, XLOOKUP, Power Query, macros)”; “Built custom GPTs and AI-assisted workflows.”
A13: • Owner-operator business acumen — ran a $465K peak-revenue multichannel business. | B13: Résumé — Julus Essentials: “$465,000 in peak annual revenue across Amazon, Walmart, eBay, StockX, and GOAT.”
A14: • Bilingual: Haitian Creole (professional), plus French. | B14: Résumé — Skills: “Haitian Creole (professional working proficiency), French.”
A16: OPPORTUNITIES | D16: THREATS
A17: Point | B17: Evidence | D17: Point | E17: Evidence
A18: • Strong local demand for bookkeeper/staff-accountant profiles that match directly. | B18: Job sheet: 50 NH/MA roles sourced Oct 23, 2026; many rated “High” fit (e.g., rows 1–3, 7, 9). | D18: • CPA-required or senior postings may screen the application out until the license is complete. | E18: Job sheet: CPA / Senior roles (rows 24, 25, 28, 41) vs. résumé CPA pathway not yet finished.
A19: • Fractional / outsourced accounting roles map 1:1 to the fractional-CFO background. | B19: Job sheet row 30 — Your Part-Time Controller, LLC, “Accountant (Fractional/Outsourced),” High fit. | D19: • Many matching roles are hourly / part-time and may fall below salary targets. | E19: Job sheet: numerous $18–$35/hr roles (rows 1, 5, 8, 13, 19, 31–33).
A20: • FP&A analyst openings leverage the KPI-dashboard & forecasting strength. | B20: Job sheet rows 14 (Buchanan Technologies, Sr. FP&A) and 42 (New Balance, Retail Financial Analyst). | D20: • Competition from candidates with full CPA or public-accounting pedigree. | E20: General market inference; résumé lists no audit-firm or Big-4 background.
A21: • Completing the remaining 25 CPA credits unlocks higher-pay, CPA-required roles. | B21: Job sheet row 28 — Pulsar Alarm Systems, CPA, $100K–$150K; vs. résumé CPA pathway in progress. | D21: • Commute / location trade-off: higher MA pay vs. NH proximity to Manchester. | E21: Job sheet: Boston/Andover/Lawrence roles vs. résumé location “Manchester, NH.”
A22: • AI/automation skillset is a differentiator in a traditional accounting market. | B22: Résumé — AI & Automation (custom GPTs, Power Query) vs. mostly conventional postings in the job sheet. | D22: • A hiring slowdown can lengthen time-to-offer and raise ghosting risk. | E22: General market inference; tracker’s 30-day “Ghosted” flag is built to monitor this.
A23: • Willingness to range across NH and Greater Boston widens the pay ceiling. | B23: Job sheet: MA roles (rows 41, 43, 46) reach $105K–$134K vs. many NH roles in the $45K–$80K band.

Sheet Lists
A1: LISTS — dropdown source values (hidden helper tab). Edit here to change dropdown options.
A2: Industries | B2: Stages | C2: WorkModes | D2: JobTypes | E2: Sources | F2: FitRatings | G2: YesNo | H2: ResumeVersions | I2: Actions | J2: Responses | K2: Methods | L2: RejectionReasons | M2: NextSteps
A3: Accounting (CPA firms) | B3: Identified | C3: On-site | D3: Full-time | E3: Indeed | F3: 1 | G3: Yes | H3: Master | I3: Found / saved | J3: No response yet | K3: LinkedIn | L3: Position filled | M3: Apply
A4: Accounting (corporate / industry) | B4: Applied | C4: Hybrid | D4: Part-time | E4: ZipRecruiter | F4: 2 | G4: No | H4: Bookkeeping-focused | I4: Applied | J4: Auto-acknowledged | K4: Email | L4: Not qualified / experience | M4: Tailor resume
A5: Government | B5: Contacted | C5: Remote | D5: Contract | E5: LinkedIn | F5: 3 | H5: Staff Accountant | I5: Resume tailored | J5: Replied | K5: Phone | L5: CPA required | M5: Follow up
A6: Nonprofit | B6: Responded | C6: Not specified | D6: Temporary | E6: Company site | F6: 4 | H6: FP&A / Analyst | I6: Called | J6: Phone screen | K6: In-person | L6: Pay mismatch | M6: Call
A7: Finance | B7: Interview | D7: Permanent | E7: Referral | F7: 5 | H7: Tax-focused | I7: Emailed | J7: Interview | K7: Referral | L7: Location / commute | M7: Send thank-you
A8: Business operations | B8: Offer | D8: Per Diem | E8: Manual | I8: Follow-up sent | J8: Offer | K8: Application portal | L8: Overqualified | M8: Schedule interview
A9: Tech / AI | B9: Rejected | D9: Not specified | I9: Contacted employee | J9: Rejected | L9: No response (ghosted) | M9: Prepare for interview
A10: Sales | B10: Ghosted | I10: Response received | J10: Ghosted | L10: Withdrew | M10: Await response
A11: Sports business | B11: Declined | I11: Interview scheduled | L11: Other | M11: Send references
A12: Other | I12: Interview completed | M12: Negotiate
I13: Thank-you sent | M13: Close out
I14: Offer received
I15: Negotiation
I16: Accepted
I17: Declined
I18: Rejected
I19: Note
